Workbook

Sheet README
A1: Verity – 500-order validation simulation (run 4, seed 0.42)
A3: What this is
A4: 500 customer orders were generated and pushed through the real Verity order functions (save_draft, submit_order) on the live database.
A5: Each order carries either no error ("clean") or one planted error. The system did not know which; its validation result is compared with the truth.
A6: The orders and the 20 customer accounts were rolled back after the run, so the live system was not changed. Only these result rows were kept.
A7: All company names, people, e-mails and phone numbers are fictional. E-mails use the reserved .example domain.
A9: Sheets
A10: Orders – one row per simulated order (raw data).
A11: Customers – the 20 fictional customer companies, with counts calculated from Orders.
A12: By error type – detection per planted error, calculated from Orders.
A13: Confusion matrix – accuracy, precision, recall, specificity and F1, calculated from Orders.
A14: Rules – how often each validation rule fired (counted when the run was analysed).
... A33: Replicate range: minimum and maximum across the three summaries. Sensitivity: replays of replicate 1 under other unusual-quantity settings.

Sheet Orders
A1: Seq | B1: Simulated day | C1: Company | D1: Contact person | E1: E-mail | F1: Phone | G1: Region | H1: Lines | I1: Units | J1: Items (SKU × qty @ unit price) | K1: Subtotal (₦) | L1: Delivery fee (₦) | M1: Tax (₦) | N1: Total (₦) | O1: Planted error | P1: Has rule | Q1: Outcome | R1: Flagged | S1: Status after submit | T1: Rules triggered | U1: Messages shown | V1: Validation time (ms)
A2: 1 | B2: 1 | C2: Greenfield Estates Nigeria | D2: Ngozi Eze | E2: ngozi.eze@greenfield7.example | F2: 08030733103 | G2: Lekki-Ajah | H2: 3 | I2: 186 | J2: PVC-2 × 2 @ 4,100; WIRE-25 × 3 @ 52,000; CEM-50 × 181 @ 9,500 | K2: 1883700 | L2: 6000 | M2: 141727.5 | N2: 2031427.5 | O2: Clean order (no error) | P2: No | Q2: warn | R2: =IF(Q2="pass","No","Yes") -> Yes | S2: pending_approval | T2: Unusual quantity | U2: Cement, 50 kg bag: 181 is far above this customer's usual 23. | V2: 10.655
A3: 2 | B3: 1 | C3: Adeyemi & Sons Construction Ltd | D3: Folake Adeyemi | E3: folake.adeyemi@adeyemi1.example | F3: 08030104729 | G3: Ikeja | H3: 1 | I3: 47 | J3: TIL-6060 × 47 @ 14,500 | K3: 681500 | L3: 4500 | M3: 51450 | N3: 737450 | O3: Clean order (no error) | P3: No | Q3: pass | R3: =IF(Q3="pass","No","Yes") -> No | S3: pending_approval | V3: 4.81
A4: 3 | B4: 1 | C4: Bodija Interiors | D4: Segun Olatunji | E4: segun.olatunji@bodija16.example | F4: 08031675664 | G4: Ibadan | H4: 1 | I4: 18 | J4: PNT-20W × 18 @ 38,000 | K4: 684000 | L4: 9000 | M4: 51975 | N4: 744975 | O4: Wrong (but valid) product chosen | P4: No | Q4: pass | R4: =IF(Q4="pass","No","Yes") -> No | S4: pending_approval | V4: 4.606
A5: 4 | B5: 1 | C5: Surulere Paint & Finish | D5: Uche Nwosu | E5: uche.nwosu@surulere12.example | F5: 08031256748 | G5: Lagos Mainland | H5: 3 | I5: 25 | J5: PVC-2 × 2 @ 4,100; NAIL-3 × 14 @ 31,000; CEM-50 × 9 @ 9,500 | K5: 527700 | L5: 4000 | M5: 39877.5 | N5: 571577.5 | O5: Quantity below minimum | P5: Yes | Q5: fail | R5: =IF(Q5="pass","No","Yes") -> Yes | S5: validation_failed | T5: Quantity limits | U5: Cement, 50 kg bag: quantity must be between 10 and 2000. | V5: 16.006
A6: 5 | B6: 1 | C6: Ola-Ade Hardware & Tiles | D6: Babatunde Oladipo | E6: babatunde.oladipo@olaade8.example | F6: 08030837832 | G6: Ikeja | H6: 3 | I6: 117 | J6: PNT-20W × 15 @ 38,000; PNT-20C × 7 @ 38,000; CEM-50 × 95 @ 9,500 | K6: 1738500 | L6: 4500 | M6: 130725 | N6: 1873725 | O6: Delivery date in the past | P6: Yes | Q6: fail | R6: =IF(Q6="pass","No","Yes") -> Yes | S6: validation_failed | T6: Delivery date & address, Unusual quantity | U6: The delivery date is in the past. | Cement, 50 kg bag: 95 is far above this customer's usual 23. | V6: 6.648
A7: 6 | B7: 1 | C7: Adeyemi & Sons Construction Ltd | D7: Folake Adeyemi | E7: folake.adeyemi@adeyemi1.example | F7: 08030104729 | G7: Ikeja | H7: 1 | I7: 47 | J7: TIL-6060 × 47 @ 14,500 | K7: 681500 | L7: 4500 | M7: 51450 | N7: 737450 | O7: Duplicate order | P7: Yes | Q7: warn | R7: =IF(Q7="pass","No","Yes") -> Yes | S7: draft | T7: Duplicate order | U7: This looks like a repeat of ORD-3195. Confirm it is a new order. | V7: 2.536
A8: 7 | B8: 1 | C8: Magodo Residential Ltd | D8: Funmilayo Adeleke | E8: funmilayo.adeleke@magodo19.example | F8: 08031989851 | G8: Ikeja | H8: 1 | I8: 9 | J8: PNT-20C × 9 @ 38,000 | K8: 342000 | L8: 4500 | M8: 25987.5 | N8: 372487.5 | O8: Wrong (but valid) product chosen | P8: No | Q8: pass | R8: =IF(Q8="pass","No","Yes") -> No | S8: pending_approval | V8: 4.713
A9: 8 | B9: 1 | C9: Yaba Tech Hub Builders | D9: Emeka Okafor | E9: emeka.okafor@yaba18.example | F9: 08031885122 | G9: Lagos Mainland | H9: 1 | I9: 203 | J9: CEM-50 × 203 @ 9,500 | K9: 1928500 | L9: 4000 | M9: 144937.5 | N9: 2077437.5 | O9: Plausible quantity typo (20 → 200) | P9: No | Q9: warn | R9: =IF(Q9="pass","No","Yes") -> Yes | S9: pending_approval | T9: Unusual quantity | U9: Cement, 50 kg bag: 203 is far above this customer's usual 23. | V9: 6.232
A10: 9 | B10: 1 | C10: Gwarinpa Homes Ltd | D10: Fatima Sani | E10: fatima.sani@gwarinpa15.example | F10: 08031570935 | G10: Abuja | H10: 3 | I10: 47 | J10: PNT-20W × 19 @ 38,000; PNT-20C × 2 @ 38,000; CEM-50 × 26 @ 9,500 | K10: 1045000 | L10: 15000 | M10: 79500 | N10: 1139500 | O10: Wrong saved address chosen | P10: No | Q10: pass | R10: =IF(Q10="pass","No","Yes") -> No | S10: pending_approval | V10: 6.485
A11: 10 | B11: 1 | C11: Victoria Island Fit-Out Ltd | D11: Chiamaka Obi | E11: chiamaka.obi@victoria17.example | F11: 08031780393 | G11: Lagos Island | H11: 1 | I11: 119 | J11: CEM-50 × 119 @ 9,500 | K11: 1130500 | L11: 5000 | M11: 85162.5 | N11: 1220662.5 | O11: Clean order (no error) | P11: No | Q11: warn | R11: =IF(Q11="pass","No","Yes") -> Yes | S11: pending_approval | T11: Unusual quantity | U11: Cement, 50 kg bag: 119 is far above this customer's usual 23. | V11: 6.738
A12: 11 | B12: 1 | C12: Victoria Island Fit-Out Ltd | D12: Chiamaka Obi | E12: chiamaka.obi@victoria17.example | F12: 08031780393 | G12: Lagos Island | H12: 2 | I12: 100 | J12: ROOF-AL × 30 @ 12,500; ROD-16 × 70 @ 11,800 | K12: 1201000 | L12: 5000 | M12: 90450 | N12: 1296450 | O12: Clean order (no error) | P12: No | Q12: pass | R12: =IF(Q12="pass","No","Yes") -> No | S12: pending_approval | V12: 2.948
A13: 12 | B13: 1 | C13: Ajah Sunrise Housing Co-op | D13: Blessing Okoro | E13: blessing.okoro@ajah14.example | F13: 08031466206 | G13: Lekki-Ajah | H13: 4 | I13: 71 | J13: SAND-T × 1 @ 185,000; ROOF-AL × 36 @ 12,500; WIRE-25 × 7 @ 52,000; CEM-50 × 27 @ 9,500 | K13: 1255500 | L13: 6000 | M13: 94612.5 | N13: 1356112.5 | O13: Discontinued product | P13: Yes | Q13: fail | R13: =IF(Q13="pass","No","Yes") -> Yes | S13: validation_failed | T13: SKU / product active, Stock availability | U13: SAND-T is no longer sold. Remove it. | Sharp sand, 20 tonne trip is out of stock. | V13: 6.525
A14: 13 | B14: 1 | C14: Victoria Island Fit-Out Ltd | D14: Chiamaka Obi | E14: chiamaka.obi@victoria17.example | F14: 08031780393 | G14: Lagos Island | H14: 2 | I14: 100 | J14: ROOF-AL × 30 @ 12,500; ROD-16 × 70 @ 11,800 | K14: 1201000 | L14: 5000 | M14: 90450 | N14: 1296450 | O14: Duplicate order | P14: Yes | Q14: warn | R14: =IF(Q14="pass","No","Yes") -> Yes | S14: draft | T14: Duplicate order | U14: This looks like a repeat of ORD-3204. Confirm it is a new order. | V14: 1.765
A15: 14 | B15: 1 | C15: Yaba Tech Hub Builders | D15: Emeka Okafor | E15: emeka.okafor@yaba18.example | F15: 08031885122 | G15: Lagos Mainland | H15: 3 | I15: 28 | J15: ROOF-AL × 11 @ 12,500; TIL-6060 × 16 @ 14,500; PNT-20C × 1 @ 38,000 | K15: 407500 | L15: 4000 | M15: 30862.5 | N15: 442362.5 | O15: Clean order (no error) | P15: No | Q15: pass | R15: =IF(Q15="pass","No","Yes") -> No | S15: pending_approval | V15: 3.562
A16: 15 | B16: 1 | C16: Lekki Coastal Developers | D16: Amina Bello | E16: amina.bello@lekki4.example | F16: 08030418916 | G16: Lekki-Ajah | H16: 4 | I16: 45 | J16: SAND-T × 1 @ 185,000; ROOF-AL × 20 @ 12,500; PNT-20W × 16 @ 38,000; PNT-20C × 8 @ 38,000 | K16: 1347000 | L16: 6000 | M16: 101475 | N16: 1454475 | O16: Discontinued product | P16: Yes | Q16: fail | R16: =IF(Q16="pass","No","Yes") -> Yes | S16: validation_failed | T16: SKU / product active, Stock availability | U16: SAND-T is no longer sold. Remove it. | Sharp sand, 20 tonne trip is out of stock. | V16: 3.303
A17: 16 | B17: 1 | C17: Oyo Central Builders | D17: Adewale Akinyemi | E17: adewale.akinyemi@oyo10.example | F17: 08031047290 | G17: (none) | H17: 2 | I17: 24 | J17: PNT-20W × 18 @ 38,000; WIRE-25 × 6 @ 52,000 | K17: 996000 | L17: 0 | M17: 74700 | N17: 1070700 | O17: Missing delivery address | P17: Yes | Q17: fail | R17: =IF(Q17="pass","No","Yes") -> Yes | S17: validation_failed | T17: Mandatory fields | U17: Choose a delivery address. | V17: 2.709
A18: 17 | B18: 1 | C18: Adeyemi & Sons Construction Ltd | D18: Folake Adeyemi | E18: folake.adeyemi@adeyemi1.example | F18: 08030104729 | G18: Ikeja | H18: 3 | I18: 76 | J18: ROOF-AL × 44 @ 12,500; WIRE-25 × 5 @ 52,000; ROD-16 × 27 @ 11,800 | K18: 1128600 | L18: 4500 | M18: 84982.5 | N18: 1218082.5 | O18: Fractional quantity | P18: Yes | Q18: fail | R18: =IF(Q18="pass","No","Yes") -> Yes | S18: validation_failed | T18: Quantity limits | U18: CEM-50 - Quantity must be a whole number | V18: 3.164
A19: 18 | B19: 1 | C19: Marina Point Facilities | D19: Kemi Lawson | E19: kemi.lawson@marina11.example | F19: 08031152019 | G19: Lagos Island | H19: 2 | I19: 873 | J19: PVC-4 × 53 @ 8,600; TIL-6060 × 820 @ 14,500 | K19: 12345800 | L19: 5000 | M19: 926310 | N19: 13277110 | O19: Quantity above maximum | P19: Yes | Q19: fail | R19: =IF(Q19="pass","No","Yes") -> Yes | S19: validation_failed | T19: Quantity limits, Stock availability | U19: Floor tile 60x60, carton: quantity must be between 2 and 800. | Floor tile 60x60, carton: not enough stock for this quantity. Reduce it. | V19: 3.028
A20: 19 | B20: 1 | C20: Bodija Interiors | D20: Segun Olatunji | E20: segun.olatunji@bodija16.example | F20: 08031675664 | G20: Ibadan | H20: 1 | I20: 3 | J20: PNT-20C × 3 @ 38,000 | K20: 114000 | L20: 9000 | M20: 9225 | N20: 132225 | O20: Clean order (no error) | P20: No | Q20: pass | R20: =IF(Q20="pass","No","Yes") -> No | S20: pending_approval | V20: 3.085
A21: 20 | B21: 1 | C21: Ola-Ade Hardware & Tiles | D21: Babatunde Oladipo | E21: babatunde.oladipo@olaade8.example | F21: 08030837832 | G21: Ikeja | H21: 1 | I21: 33 | J21: ROD-16 × 33 @ 11,800 | K21: 389400 | L21: 4500 | M21: 29542.5 | N21: 423442.5 | O21: Clean order (no error) | P21: No | Q21: pass | R21: =IF(Q21="pass","No","Yes") -> No | S21: pending_approval | V21: 3.016
A22: 21 | B22: 1 | C22: Ajah Sunrise Housing Co-op | D22: Blessing Okoro | E22: blessing.okoro@ajah14.example | F22: 08031466206 | G22: Lekki-Ajah | H22: 2 | I22: 125 | J22: ROD-12 × 65 @ 7,200; CEM-50 × 60 @ 9,500 | K22: 1038000 | L22: 6000 | M22: 78300 | N22: 1122300 | O22: Wrong saved address chosen | P22: No | Q22: warn | R22: =IF(Q22="pass","No","Yes") -> Yes | S22: pending_approval | T22: Unusual quantity | U22: Iron rod, 12 mm: 65 is far above this customer's usual 13. | V22: 10.714
A23: 22 | B23: 1 | C23: Ibadan Prime Homes Ltd | D23: Oluwaseun Afolabi | E23: oluwaseun.afolabi@ibadan3.example | F23: 08030314187 | G23: Ibadan | H23: 4 | I23: 511 | J23: PVC-4 × 27 @ 8,600; ROOF-AL × 57 @ 12,500; ROD-12 × 126 @ 7,200; ROD-16 × 301 @ 11,800 | K23: 5403700 | L23: 9000 | M23: 405952.5 | N23: 5818652.5 | O23: Quantity above available stock | P23: Yes | Q23: fail | R23: =IF(Q23="pass","No","Yes") -> Yes | S23: validation_failed | T23: Stock availability, Unusual quantity | U23: Iron rod, 16 mm: not enough stock for this quantity. Reduce it. | Iron rod, 12 mm: 126 is far above this customer's usual 13. | V23: 7.158
A24: 23 | B24: 1 | C24: Lekki Coastal Developers | D24: Amina Bello | E24: amina.bello@lekki4.example | F24: 08030418916 | G24: (none) | H24: 2 | I24: 16 | J24: PVC-2 × 2 @ 4,100; ROD-16 × 14 @ 11,800 | K24: 173400 | L24: 0 | M24: 13005 | N24: 186405 | O24: Missing delivery address | P24: Yes | Q24: fail | R24: =IF(Q24="pass","No","Yes") -> Yes | S24: validation_failed | T24: Mandatory fields | U24: Choose a delivery address. | V24: 2.859
A25: 24 | B25: 1 | C25: Yaba Tech Hub Builders | D25: Emeka Okafor | E25: emeka.okafor@yaba18.example | F25: 08031885122 | G25: Lagos Mainland | H25: 3 | I25: 124 | J25: ROD-12 × 109 @ 7,200; PVC-2 × 2 @ 4,100; NAIL-3 × 13 @ 31,000 | K25: 1196000 | L25: 4000 | M25: 90000 | N25: 1290000 | O25: Clean order (no error) | P25: No | Q25: warn | R25: =IF(Q25="pass","No","Yes") -> Yes | S25: pending_approval | T25: Unusual quantity | U25: Iron rod, 12 mm: 109 is far above this customer's usual 13. | V25: 7.385
A26: 25 | B26: 1 | C26: Apapa Port Works Supplies | D26: Garba Usman | E26: garba.usman@apapa20.example | F26: 08032094580 | G26: Lagos Mainland | H26: 3 | I26: 133 | J26: PVC-4 × 32 @ 8,600; ROOF-AL × 61 @ 12,500; TIL-6060 × 40 @ 14,500 | K26: 1617700 | L26: 4000 | M26: 121627.5 | N26: 1743327.5 | O26: Clean order (no error) | P26: No | Q26: pass | R26: =IF(Q26="pass","No","Yes") -> No | S26: pending_approval | V26: 3.827
A27: 26 | B27: 1 | C27: Surulere Paint & Finish | D27: Uche Nwosu | E27: uche.nwosu@surulere12.example | F27: 08031256748 | G27: Lagos Mainland | H27: 1 | I27: 104 | J27: CEM-50 × 104 @ 9,500 | K27: 988000 | L27: 4000 | M27: 74400 | N27: 1066400 | O27: Fractional quantity | P27: Yes | Q27: fail | R27: =IF(Q27="pass","No","Yes") -> Yes | S27: validation_failed | T27: Quantity limits, Unusual quantity | U27: PVC-4 - Quantity must be a whole number | Cement, 50 kg bag: 104 is far above this customer's usual 23. | V27: 6.991
A28: 27 | B28: 1 | C28: Victoria Island Fit-Out Ltd | D28: Chiamaka Obi | E28: chiamaka.obi@victoria17.example | F28: 08031780393 | G28: Lagos Island | H28: 1 | I28: 60 | J28: PVC-4 × 60 @ 8,600 | K28: 516000 | L28: 5000 | M28: 39075 | N28: 560075 | O28: Wrong saved address chosen | P28: No | Q28: pass | R28: =IF(Q28="pass","No","Yes") -> No | S28: pending_approval | V28: 3.232
A29: 28 | B29: 1 | C29: Eko Bridge Contractors | D29: Tolulope Ogunleye | E29: tolulope.ogunleye@eko6.example | F29: 08030628374 | G29: Lagos Island | H29: 3 | I29: 68 | J29: PVC-4 × 61 @ 8,600; PVC-2 × 2 @ 4,100; NAIL-3 × 5 @ 31,000 | K29: 687800 | L29: 5000 | M29: 51960 | N29: 744760 | O29: Wrong saved address chosen | P29: No | Q29: pass | R29: =IF(Q29="pass","No","Yes") -> No | S29: pending_approval | V29: 3.709
A30: 29 | B30: 1 | C30: Northgate Realty Abuja | D30: Ibrahim Musa | E30: ibrahim.musa@northgate5.example | F30: 08030523645 | G30: Abuja | H30: 3 | I30: 84 | J30: ROOF-AL × 56 @ 12,500; PNT-20W × 15 @ 38,000; WIRE-25 × 13 @ 52,000 | K30: 1946000 | L30: 15000 | M30: 147075 | N30: 2108075 | O30: Clean order (no error) | P30: No | Q30: pass | R30: =IF(Q30="pass","No","Yes") -> No | S30: pending_approval | V30: 3.971
A31: 30 | B31: 1 | C31: Apapa Port Works Supplies | D31: Garba Usman | E31: garba.usman@apapa20.example | F31: 08032094580 | G31: Lagos Mainland | H31: 4 | I31: 1065 | J31: PVC-4 × 14 @ 8,600; ROOF-AL × 31 @ 12,500; NAIL-3 × 4 @ 31,000; ROD-16 × 1016 @ 11,800 | K31: 12620700 | L31: 4000 | M31: 946852.5 | N31: 13571552 | O31: Quantity above maximum | P31: Yes | Q31: fail | R31: =IF(Q31="pass","No","Yes") -> Yes | S31: validation_failed | T31: Quantity limits, Stock availability | U31: Iron rod, 16 mm: quantity must be between 5 and 1000. | Iron rod, 16 mm: not enough stock for this quantity. Reduce it. | V31: 4.201
A32: 31 | B32: 1 | C32: Kanu Brothers Building Supplies | D32: Chukwuemeka Kanu | E32: chukwuemeka.kanu@kanu2.example | F32: 08030209458 | G32: Lagos Mainland | H32: 3 | I32: 14 | J32: PNT-20C × 6 @ 38,000; PVC-2 × 2 @ 4,100; NAIL-3 × 6 @ 31,000 | K32: 422200 | L32: 4000 | M32: 31965 | N32: 458165 | O32: Clean order (no error) | P32: No | Q32: pass | R32: =IF(Q32="pass","No","Yes") -> No | S32: pending_approval | V32: 4.006
A33: 32 | B33: 1 | C33: Lekki Coastal Developers | D33: Amina Bello | E33: amina.bello@lekki4.example | F33: 08030418916 | G33: (none) | H33: 3 | I33: 18 | J33: PVC-2 × 2 @ 4,100; NAIL-3 × 5 @ 31,000; WIRE-25 × 11 @ 52,000 | K33: 735200 | L33: 0 | M33: 55140 | N33: 790340 | O33: Missing delivery address | P33: Yes | Q33: fail | R33: =IF(Q33="pass","No","Yes") -> Yes | S33: validation_failed | T33: Mandatory fields | U33: Choose a delivery address. | V33: 3.365
A34: 33 | B34: 1 | C34: Marina Point Facilities | D34: Kemi Lawson | E34: kemi.lawson@marina11.example | F34: 08031152019 | G34: Lagos Island | H34: 1 | I34: 29 | J34: TIL-6060 × 29 @ 14,500 | K34: 420500 | L34: 5000 | M34: 31912.5 | N34: 457412.5 | O34: Clean order (no error) | P34: No | Q34: pass | R34: =IF(Q34="pass","No","Yes") -> No | S34: pending_approval | V34: 3.305
A35: 34 | B35: 1 | C35: Adeyemi & Sons Construction Ltd | D35: Folake Adeyemi | E35: folake.adeyemi@adeyemi1.example | F35: 08030104729 | G35: Ikeja | H35: 0 | I35: 0 | K35: 0 | L35: 4500 | M35: 337.5 | N35: 4837.5 | O35: Wrong (but valid) product chosen | P35: No | Q35: fail | R35: =IF(Q35="pass","No","Yes") -> Yes | S35: validation_failed | T35: Quantity limits | U35: line - Quantity must be a whole number | V35: 2.424
A36: 35 | B36: 1 | C36: Marina Point Facilities | D36: Kemi Lawson | E36: kemi.lawson@marina11.example | F36: 08031152019 | G36: Lagos Island | H36: 1 | I36: 123 | J36: ROD-12 × 123 @ 7,200 | K36: 885600 | L36: 5000 | M36: 66795 | N36: 957395 | O36: Clean order (no error) | P36: No | Q36: warn | R36: =IF(Q36="pass","No","Yes") -> Yes | S36: pending_approval | T36: Unusual quantity | U36: Iron rod, 12 mm: 123 is far above this customer's usual 13. | V36: 7.18
A37: 36 | B37: 1 | C37: Marina Point Facilities | D37: Kemi Lawson | E37: kemi.lawson@marina11.example | F37: 08031152019 | G37: Lagos Island | H37: 2 | I37: 263 | J37: PVC-4 × 251 @ 8,600; WIRE-25 × 12 @ 52,000 | K37: 2782600 | L37: 5000 | M37: 209070 | N37: 2996670 | O37: Quantity above available stock | P37: Yes | Q37: fail | R37: =IF(Q37="pass","No","Yes") -> Yes | S37: validation_failed | T37: Stock availability | U37: PVC pipe, 4 inch, 6 m: not enough stock for this quantity. Reduce it. | V37: 3.491
A38: 37 | B38: 1 | C38: Surulere Paint & Finish | D38: Uche Nwosu | E38: uche.nwosu@surulere12.example | F38: 08031256748 | G38: Lagos Mainland | H38: 2 | I38: 50 | J38: TIL-6060 × 48 @ 14,500; PVC-2 × 2 @ 4,100 | K38: 704200 | L38: 4000 | M38: 53115 | N38: 761315 | O38: Clean order (no error) | P38: No | Q38: pass | R38: =IF(Q38="pass","No","Yes") -> No | S38: pending_approval | V38: 3.895
A39: 38 | B39: 1 | C39: Ajah Sunrise Housing Co-op | D39: Blessing Okoro | E39: blessing.okoro@ajah14.example | F39: 08031466206 | G39: Lekki-Ajah | H39: 3 | I39: 91 | J39: PVC-4 × 44 @ 8,600; ROOF-AL × 39 @ 12,500; PNT-20C × 8 @ 38,000 | K39: 1169900 | L39: 6000 | M39: 88192.5 | N39: 1264092.5 | O39: Clean order (no error) | P39: No | Q39: pass | R39: =IF(Q39="pass","No","Yes") -> No | S39: pending_approval | V39: 4.634
A40: 39 | B40: 1 | C40: Agege Steel Works | D40: Yusuf Adebanjo | E40: yusuf.adebanjo@agege13.example | F40: 08031361477 | G40: Ikeja | H40: 3 | I40: 117 | J40: ROOF-AL × 43 @ 12,500; ROD-12 × 68 @ 7,200; PNT-20C × 6 @ 38,000 | K40: 1255100 | L40: 4500 | M40: 94470 | N40: 1354070 | O40: Clean order (no error) | P40: No | Q40: warn | R40: =IF(Q40="pass","No","Yes") -> Yes | S40: pending_approval | T40: Unusual quantity | U40: Iron rod, 12 mm: 68 is far above this customer's usual 13. | V40: 8.802
...

Sheet Customers
A1: Company | B1: Contact person | C1: E-mail | D1: Phone | E1: Region | F1: Orders | G1: Passed | H1: Warned | I1: Blocked | J1: Order value (₦)
A2: Adeyemi & Sons Construction Ltd | B2: Folake Adeyemi | C2: folake.adeyemi@adeyemi1.example | D2: 08030104729 | E2: Ikeja | F2: =COUNTIF(Orders!$C$2:$C$501,A2) -> 26 | G2: =COUNTIFS(Orders!$C$2:$C$501,A2,Orders!$Q$2:$Q$501,"pass") -> 8 | H2: =COUNTIFS(Orders!$C$2:$C$501,A2,Orders!$Q$2:$Q$501,"warn") -> 4 | I2: =COUNTIFS(Orders!$C$2:$C$501,A2,Orders!$Q$2:$Q$501,"fail") -> 14 | J2: =SUMIF(Orders!$C$2:$C$501,A2,Orders!$N$2:$N$501) -> 32484672
A3: Agege Steel Works | B3: Yusuf Adebanjo | C3: yusuf.adebanjo@agege13.example | D3: 08031361477 | E3: Ikeja | F3: =COUNTIF(Orders!$C$2:$C$501,A3) -> 28 | G3: =COUNTIFS(Orders!$C$2:$C$501,A3,Orders!$Q$2:$Q$501,"pass") -> 12 | H3: =COUNTIFS(Orders!$C$2:$C$501,A3,Orders!$Q$2:$Q$501,"warn") -> 5 | I3: =COUNTIFS(Orders!$C$2:$C$501,A3,Orders!$Q$2:$Q$501,"fail") -> 11 | J3: =SUMIF(Orders!$C$2:$C$501,A3,Orders!$N$2:$N$501) -> 56063938
A4: Ajah Sunrise Housing Co-op | B4: Blessing Okoro | C4: blessing.okoro@ajah14.example | D4: 08031466206 | E4: Lekki-Ajah | F4: =COUNTIF(Orders!$C$2:$C$501,A4) -> 23 | G4: =COUNTIFS(Orders!$C$2:$C$501,A4,Orders!$Q$2:$Q$501,"pass") -> 9 | H4: =COUNTIFS(Orders!$C$2:$C$501,A4,Orders!$Q$2:$Q$501,"warn") -> 3 | I4: =COUNTIFS(Orders!$C$2:$C$501,A4,Orders!$Q$2:$Q$501,"fail") -> 11 | J4: =SUMIF(Orders!$C$2:$C$501,A4,Orders!$N$2:$N$501) -> 38500265
A5: Apapa Port Works Supplies | B5: Garba Usman | C5: garba.usman@apapa20.example | D5: 08032094580 | E5: Lagos Mainland | F5: =COUNTIF(Orders!$C$2:$C$501,A5) -> 25 | G5: =COUNTIFS(Orders!$C$2:$C$501,A5,Orders!$Q$2:$Q$501,"pass") -> 13 | H5: =COUNTIFS(Orders!$C$2:$C$501,A5,Orders!$Q$2:$Q$501,"warn") -> 2 | I5: =COUNTIFS(Orders!$C$2:$C$501,A5,Orders!$Q$2:$Q$501,"fail") -> 10 | J5: =SUMIF(Orders!$C$2:$C$501,A5,Orders!$N$2:$N$501) -> 61697690
A6: Bodija Interiors | B6: Segun Olatunji | C6: segun.olatunji@bodija16.example | D6: 08031675664 | E6: Ibadan | F6: =COUNTIF(Orders!$C$2:$C$501,A6) -> 19 | G6: =COUNTIFS(Orders!$C$2:$C$501,A6,Orders!$Q$2:$Q$501,"pass") -> 10 | H6: =COUNTIFS(Orders!$C$2:$C$501,A6,Orders!$Q$2:$Q$501,"warn") -> 3 | I6: =COUNTIFS(Orders!$C$2:$C$501,A6,Orders!$Q$2:$Q$501,"fail") -> 6 | J6: =SUMIF(Orders!$C$2:$C$501,A6,Orders!$N$2:$N$501) -> 38501878
A7: Eko Bridge Contractors | B7: Tolulope Ogunleye | C7: tolulope.ogunleye@eko6.example | D7: 08030628374 | E7: Lagos Island | F7: =COUNTIF(Orders!$C$2:$C$501,A7) -> 28 | G7: =COUNTIFS(Orders!$C$2:$C$501,A7,Orders!$Q$2:$Q$501,"pass") -> 17 | H7: =COUNTIFS(Orders!$C$2:$C$501,A7,Orders!$Q$2:$Q$501,"warn") -> 3 | I7: =COUNTIFS(Orders!$C$2:$C$501,A7,Orders!$Q$2:$Q$501,"fail") -> 8 | J7: =SUMIF(Orders!$C$2:$C$501,A7,Orders!$N$2:$N$501) -> 30560852
A8: Greenfield Estates Nigeria | B8: Ngozi Eze | C8: ngozi.eze@greenfield7.example | D8: 08030733103 | E8: Lekki-Ajah | F8: =COUNTIF(Orders!$C$2:$C$501,A8) -> 29 | G8: =COUNTIFS(Orders!$C$2:$C$501,A8,Orders!$Q$2:$Q$501,"pass") -> 16 | H8: =COUNTIFS(Orders!$C$2:$C$501,A8,Orders!$Q$2:$Q$501,"warn") -> 7 | I8: =COUNTIFS(Orders!$C$2:$C$501,A8,Orders!$Q$2:$Q$501,"fail") -> 6 | J8: =SUMIF(Orders!$C$2:$C$501,A8,Orders!$N$2:$N$501) -> 36477008
A9: Gwarinpa Homes Ltd | B9: Fatima Sani | C9: fatima.sani@gwarinpa15.example | D9: 08031570935 | E9: Abuja | F9: =COUNTIF(Orders!$C$2:$C$501,A9) -> 20 | G9: =COUNTIFS(Orders!$C$2:$C$501,A9,Orders!$Q$2:$Q$501,"pass") -> 10 | H9: =COUNTIFS(Orders!$C$2:$C$501,A9,Orders!$Q$2:$Q$501,"warn") -> 4 | I9: =COUNTIFS(Orders!$C$2:$C$501,A9,Orders!$Q$2:$Q$501,"fail") -> 6 | J9: =SUMIF(Orders!$C$2:$C$501,A9,Orders!$N$2:$N$501) -> 17387588
A10: Ibadan Prime Homes Ltd | B10: Oluwaseun Afolabi | C10: oluwaseun.afolabi@ibadan3.example | D10: 08030314187 | E10: Ibadan | F10: =COUNTIF(Orders!$C$2:$C$501,A10) -> 19 | G10: =COUNTIFS(Orders!$C$2:$C$501,A10,Orders!$Q$2:$Q$501,"pass") -> 8 | H10: =COUNTIFS(Orders!$C$2:$C$501,A10,Orders!$Q$2:$Q$501,"warn") -> 3 | I10: =COUNTIFS(Orders!$C$2:$C$501,A10,Orders!$Q$2:$Q$501,"fail") -> 8 | J10: =SUMIF(Orders!$C$2:$C$501,A10,Orders!$N$2:$N$501) -> 43504928
A11: Kanu Brothers Building Supplies | B11: Chukwuemeka Kanu | C11: chukwuemeka.kanu@kanu2.example | D11: 08030209458 | E11: Lagos Mainland | F11: =COUNTIF(Orders!$C$2:$C$501,A11) -> 20 | G11: =COUNTIFS(Orders!$C$2:$C$501,A11,Orders!$Q$2:$Q$501,"pass") -> 12 | H11: =COUNTIFS(Orders!$C$2:$C$501,A11,Orders!$Q$2:$Q$501,"warn") -> 5 | I11: =COUNTIFS(Orders!$C$2:$C$501,A11,Orders!$Q$2:$Q$501,"fail") -> 3 | J11: =SUMIF(Orders!$C$2:$C$501,A11,Orders!$N$2:$N$501) -> 17268692
A12: Lekki Coastal Developers | B12: Amina Bello | C12: amina.bello@lekki4.example | D12: 08030418916 | E12: Lekki-Ajah | F12: =COUNTIF(Orders!$C$2:$C$501,A12) -> 25 | G12: =COUNTIFS(Orders!$C$2:$C$501,A12,Orders!$Q$2:$Q$501,"pass") -> 15 | H12: =COUNTIFS(Orders!$C$2:$C$501,A12,Orders!$Q$2:$Q$501,"warn") -> 3 | I12: =COUNTIFS(Orders!$C$2:$C$501,A12,Orders!$Q$2:$Q$501,"fail") -> 7 | J12: =SUMIF(Orders!$C$2:$C$501,A12,Orders!$N$2:$N$501) -> 22656485
A13: Magodo Residential Ltd | B13: Funmilayo Adeleke | C13: funmilayo.adeleke@magodo19.example | D13: 08031989851 | E13: Ikeja | F13: =COUNTIF(Orders!$C$2:$C$501,A13) -> 25 | G13: =COUNTIFS(Orders!$C$2:$C$501,A13,Orders!$Q$2:$Q$501,"pass") -> 7 | H13: =COUNTIFS(Orders!$C$2:$C$501,A13,Orders!$Q$2:$Q$501,"warn") -> 3 | I13: =COUNTIFS(Orders!$C$2:$C$501,A13,Orders!$Q$2:$Q$501,"fail") -> 15 | J13: =SUMIF(Orders!$C$2:$C$501,A13,Orders!$N$2:$N$501) -> 35261505
... A21: Zuma Rock Engineering | B21: Hauwa Abdullahi | C21: hauwa.abdullahi@zuma9.example | D21: 08030942561 | E21: Abuja | F21: =COUNTIF(Orders!$C$2:$C$501,A21) -> 26 | G21: =COUNTIFS(Orders!$C$2:$C$501,A21,Orders!$Q$2:$Q$501,"pass") -> 8 | H21: =COUNTIFS(Orders!$C$2:$C$501,A21,Orders!$Q$2:$Q$501,"warn") -> 6 | I21: =COUNTIFS(Orders!$C$2:$C$501,A21,Orders!$Q$2:$Q$501,"fail") -> 12 | J21: =SUMIF(Orders!$C$2:$C$501,A21,Orders!$N$2:$N$501) -> 32239788
A22: Total | F22: =SUM(F2:F21) -> 500 | G22: =SUM(G2:G21) -> 233 | H22: =SUM(H2:H21) -> 75 | I22: =SUM(I2:I21) -> 192 | J22: =SUM(J2:J21) -> 717846085

Sheet By error type
A1: Planted error | B1: Has rule | C1: Orders | D1: Blocked | E1: Warned | F1: Passed | G1: Flagged | H1: Detection rate | I1: Note
A2: Clean order (no error) | B2: No | C2: =COUNTIF(Orders!$O$2:$O$501,A2) -> 216 | D2: =COUNTIFS(Orders!$O$2:$O$501,A2,Orders!$Q$2:$Q$501,"fail") -> 0 | E2: =COUNTIFS(Orders!$O$2:$O$501,A2,Orders!$Q$2:$Q$501,"warn") -> 33 | F2: =COUNTIFS(Orders!$O$2:$O$501,A2,Orders!$Q$2:$Q$501,"pass") -> 183 | G2: =D2+E2 -> 33 | H2: =IF(C2=0,0,G2/C2) -> 0.15277778 | I2: For clean orders the "detection rate" is a false-alarm rate; lower is better.
A3: SKU not in catalogue | B3: Yes | C3: =COUNTIF(Orders!$O$2:$O$501,A3) -> 20 | D3: =COUNTIFS(Orders!$O$2:$O$501,A3,Orders!$Q$2:$Q$501,"fail") -> 20 | E3: =COUNTIFS(Orders!$O$2:$O$501,A3,Orders!$Q$2:$Q$501,"warn") -> 0 | F3: =COUNTIFS(Orders!$O$2:$O$501,A3,Orders!$Q$2:$Q$501,"pass") -> 0 | G3: =D3+E3 -> 20 | H3: =IF(C3=0,0,G3/C3) -> 1
A4: Missing delivery address | B4: Yes | C4: =COUNTIF(Orders!$O$2:$O$501,A4) -> 22 | D4: =COUNTIFS(Orders!$O$2:$O$501,A4,Orders!$Q$2:$Q$501,"fail") -> 22 | E4: =COUNTIFS(Orders!$O$2:$O$501,A4,Orders!$Q$2:$Q$501,"warn") -> 0 | F4: =COUNTIFS(Orders!$O$2:$O$501,A4,Orders!$Q$2:$Q$501,"pass") -> 0 | G4: =D4+E4 -> 22 | H4: =IF(C4=0,0,G4/C4) -> 1
A5: Missing delivery date | B5: Yes | C5: =COUNTIF(Orders!$O$2:$O$501,A5) -> 11 | D5: =COUNTIFS(Orders!$O$2:$O$501,A5,Orders!$Q$2:$Q$501,"fail") -> 11 | E5: =COUNTIFS(Orders!$O$2:$O$501,A5,Orders!$Q$2:$Q$501,"warn") -> 0 | F5: =COUNTIFS(Orders!$O$2:$O$501,A5,Orders!$Q$2:$Q$501,"pass") -> 0 | G5: =D5+E5 -> 11 | H5: =IF(C5=0,0,G5/C5) -> 1
A6: Delivery date in the past | B6: Yes | C6: =COUNTIF(Orders!$O$2:$O$501,A6) -> 19 | D6: =COUNTIFS(Orders!$O$2:$O$501,A6,Orders!$Q$2:$Q$501,"fail") -> 19 | E6: =COUNTIFS(Orders!$O$2:$O$501,A6,Orders!$Q$2:$Q$501,"warn") -> 0 | F6: =COUNTIFS(Orders!$O$2:$O$501,A6,Orders!$Q$2:$Q$501,"pass") -> 0 | G6: =D6+E6 -> 19 | H6: =IF(C6=0,0,G6/C6) -> 1
A7: Quantity below minimum | B7: Yes | C7: =COUNTIF(Orders!$O$2:$O$501,A7) -> 23 | D7: =COUNTIFS(Orders!$O$2:$O$501,A7,Orders!$Q$2:$Q$501,"fail") -> 23 | E7: =COUNTIFS(Orders!$O$2:$O$501,A7,Orders!$Q$2:$Q$501,"warn") -> 0 | F7: =COUNTIFS(Orders!$O$2:$O$501,A7,Orders!$Q$2:$Q$501,"pass") -> 0 | G7: =D7+E7 -> 23 | H7: =IF(C7=0,0,G7/C7) -> 1
A8: Quantity above maximum | B8: Yes | C8: =COUNTIF(Orders!$O$2:$O$501,A8) -> 15 | D8: =COUNTIFS(Orders!$O$2:$O$501,A8,Orders!$Q$2:$Q$501,"fail") -> 15 | E8: =COUNTIFS(Orders!$O$2:$O$501,A8,Orders!$Q$2:$Q$501,"warn") -> 0 | F8: =COUNTIFS(Orders!$O$2:$O$501,A8,Orders!$Q$2:$Q$501,"pass") -> 0 | G8: =D8+E8 -> 15 | H8: =IF(C8=0,0,G8/C8) -> 1
A9: Fractional quantity | B9: Yes | C9: =COUNTIF(Orders!$O$2:$O$501,A9) -> 28 | D9: =COUNTIFS(Orders!$O$2:$O$501,A9,Orders!$Q$2:$Q$501,"fail") -> 28 | E9: =COUNTIFS(Orders!$O$2:$O$501,A9,Orders!$Q$2:$Q$501,"warn") -> 0 | F9: =COUNTIFS(Orders!$O$2:$O$501,A9,Orders!$Q$2:$Q$501,"pass") -> 0 | G9: =D9+E9 -> 28 | H9: =IF(C9=0,0,G9/C9) -> 1
A10: Quantity above available stock | B10: Yes | C10: =COUNTIF(Orders!$O$2:$O$501,A10) -> 16 | D10: =COUNTIFS(Orders!$O$2:$O$501,A10,Orders!$Q$2:$Q$501,"fail") -> 16 | E10: =COUNTIFS(Orders!$O$2:$O$501,A10,Orders!$Q$2:$Q$501,"warn") -> 0 | F10: =COUNTIFS(Orders!$O$2:$O$501,A10,Orders!$Q$2:$Q$501,"pass") -> 0 | G10: =D10+E10 -> 16 | H10: =IF(C10=0,0,G10/C10) -> 1
A11: Duplicate order | B11: Yes | C11: =COUNTIF(Orders!$O$2:$O$501,A11) -> 18 | D11: =COUNTIFS(Orders!$O$2:$O$501,A11,Orders!$Q$2:$Q$501,"fail") -> 0 | E11: =COUNTIFS(Orders!$O$2:$O$501,A11,Orders!$Q$2:$Q$501,"warn") -> 18 | F11: =COUNTIFS(Orders!$O$2:$O$501,A11,Orders!$Q$2:$Q$501,"pass") -> 0 | G11: =D11+E11 -> 18 | H11: =IF(C11=0,0,G11/C11) -> 1
A12: Discontinued product | B12: Yes | C12: =COUNTIF(Orders!$O$2:$O$501,A12) -> 25 | D12: =COUNTIFS(Orders!$O$2:$O$501,A12,Orders!$Q$2:$Q$501,"fail") -> 25 | E12: =COUNTIFS(Orders!$O$2:$O$501,A12,Orders!$Q$2:$Q$501,"warn") -> 0 | F12: =COUNTIFS(Orders!$O$2:$O$501,A12,Orders!$Q$2:$Q$501,"pass") -> 0 | G12: =D12+E12 -> 25 | H12: =IF(C12=0,0,G12/C12) -> 1
A13: Wrong (but valid) product chosen | B13: No | C13: =COUNTIF(Orders!$O$2:$O$501,A13) -> 35 | D13: =COUNTIFS(Orders!$O$2:$O$501,A13,Orders!$Q$2:$Q$501,"fail") -> 13 | E13: =COUNTIFS(Orders!$O$2:$O$501,A13,Orders!$Q$2:$Q$501,"warn") -> 1 | F13: =COUNTIFS(Orders!$O$2:$O$501,A13,Orders!$Q$2:$Q$501,"pass") -> 21 | G13: =D13+E13 -> 14 | H13: =IF(C13=0,0,G13/C13) -> 0.4 | I13: Flagged only by unrelated rules: Quantity limits ×13, Duplicate order ×1
A14: Plausible quantity typo (20 → 200) | B14: No | C14: =COUNTIF(Orders!$O$2:$O$501,A14) -> 30 | D14: =COUNTIFS(Orders!$O$2:$O$501,A14,Orders!$Q$2:$Q$501,"fail") -> 0 | E14: =COUNTIFS(Orders!$O$2:$O$501,A14,Orders!$Q$2:$Q$501,"warn") -> 19 | F14: =COUNTIFS(Orders!$O$2:$O$501,A14,Orders!$Q$2:$Q$501,"pass") -> 11 | G14: =D14+E14 -> 19 | H14: =IF(C14=0,0,G14/C14) -> 0.63333333 | I14: Flagged only by unrelated rules: Unusual quantity ×17, Duplicate order ×2
A15: Wrong saved address chosen | B15: No | C15: =COUNTIF(Orders!$O$2:$O$501,A15) -> 22 | D15: =COUNTIFS(Orders!$O$2:$O$501,A15,Orders!$Q$2:$Q$501,"fail") -> 0 | E15: =COUNTIFS(Orders!$O$2:$O$501,A15,Orders!$Q$2:$Q$501,"warn") -> 4 | F15: =COUNTIFS(Orders!$O$2:$O$501,A15,Orders!$Q$2:$Q$501,"pass") -> 18 | G15: =D15+E15 -> 4 | H15: =IF(C15=0,0,G15/C15) -> 0.18181818 | I15: Flagged only by unrelated rules: Unusual quantity ×4
A16: Total | C16: =SUM(C2:C15) -> 500 | D16: =SUM(D2:D15) -> 192 | E16: =SUM(E2:E15) -> 75 | F16: =SUM(F2:F15) -> 233 | G16: =SUM(G2:G15) -> 267

Sheet Confusion matrix
A1: Binary view: does the order contain an error, and did the system flag it (warn or fail)?
A3: A. All 500 orders (every planted error, including those no rule targets)
B4: Flagged by system | C4: Passed by system | D4: Total
A5: Order has an error | B5: =COUNTIFS(Orders!$O$2:$O$501,"<>Clean order (no error)",Orders!$Q$2:$Q$501,"<>pass") -> 234 | C5: =COUNTIFS(Orders!$O$2:$O$501,"<>Clean order (no error)",Orders!$Q$2:$Q$501,"pass") -> 50 | D5: =B5+C5 -> 284
A6: Clean order | B6: =COUNTIFS(Orders!$O$2:$O$501,"Clean order (no error)",Orders!$Q$2:$Q$501,"<>pass") -> 33 | C6: =COUNTIFS(Orders!$O$2:$O$501,"Clean order (no error)",Orders!$Q$2:$Q$501,"pass") -> 183 | D6: =B6+C6 -> 216
A8: Accuracy | B8: =(B5+C6)/(B5+C5+B6+C6) -> 0.834 | C8: (TP+TN) / all orders
A9: Precision | B9: =B5/(B5+B6) -> 0.87640449 | C9: of flagged orders, share that really had an error
A10: Recall (detection rate) | B10: =B5/(B5+C5) -> 0.82394366 | C10: of erroneous orders, share flagged
A11: Specificity | B11: =C6/(C6+B6) -> 0.84722222 | C11: of clean orders, share passed without a flag
A12: F1 score | B12: =2*B9*B10/(B9+B10) -> 0.84936479 | C12: harmonic mean of precision and recall
A15: B. Only error types a rule is designed for, plus all clean orders
B16: Flagged by system | C16: Passed by system | D16: Total
A17: Order has an error | B17: =COUNTIFS(Orders!$O$2:$O$501,"<>Clean order (no error)",Orders!$P$2:$P$501,"Yes",Orders!$Q$2:$Q$501,"<>pass") -> 197 | C17: =COUNTIFS(Orders!$O$2:$O$501,"<>Clean order (no error)",Orders!$P$2:$P$501,"Yes",Orders!$Q$2:$Q$501,"pass") -> 0 | D17: =B17+C17 -> 197
A18: Clean order | B18: =COUNTIFS(Orders!$O$2:$O$501,"Clean order (no error)",Orders!$Q$2:$Q$501,"<>pass") -> 33 | C18: =COUNTIFS(Orders!$O$2:$O$501,"Clean order (no error)",Orders!$Q$2:$Q$501,"pass") -> 183 | D18: =B18+C18 -> 216
A20: Accuracy | B20: =(B17+C18)/(B17+C17+B18+C18) -> 0.92009685 | C20: (TP+TN) / all orders
A21: Precision | B21: =B17/(B17+B18) -> 0.85652174 | C21: of flagged orders, share that really had an error
A22: Recall (detection rate) | B22: =B17/(B17+C17) -> 1 | C22: of erroneous orders, share flagged
A23: Specificity | B23: =C18/(C18+B18) -> 0.84722222 | C23: of clean orders, share passed without a flag
A24: F1 score | B24: =2*B21*B22/(B21+B22) -> 0.92271663 | C24: harmonic mean of precision and recall

Sheet Rules
A1: Validation rule | B1: Severity | C1: Orders it fired on | D1: On orders with a planted error | E1: On clean orders (false alarms) | F1: False-alarm share
A2: Unusual quantity | B2: Warning | C2: 93 | D2: 61 | E2: 32 | F2: =IF(C2=0,0,E2/C2) -> 0.34408602
A3: Quantity limits | B3: Blocking | C3: 79 | D3: 79 | E3: 0 | F3: =IF(C3=0,0,E3/C3) -> 0
A4: Stock availability | B4: Blocking | C4: 56 | D4: 56 | E4: 0 | F4: =IF(C4=0,0,E4/C4) -> 0
A5: SKU / product active | B5: Blocking | C5: 45 | D5: 45 | E5: 0 | F5: =IF(C5=0,0,E5/C5) -> 0
A6: Mandatory fields | B6: Blocking | C6: 33 | D6: 33 | E6: 0 | F6: =IF(C6=0,0,E6/C6) -> 0
A7: Duplicate order | B7: Warning | C7: 22 | D7: 21 | E7: 1 | F7: =IF(C7=0,0,E7/C7) -> 0.045454545
A8: Delivery date & address | B8: Blocking | C8: 19 | D8: 19 | E8: 0 | F8: =IF(C8=0,0,E8/C8) -> 0
A10: Counts taken from the "Rules triggered" column of Orders when the run was analysed (an order can trigger several rules).

Sheet Timing
A1: Statistic | B1: Validation time (ms)
A2: Orders measured | B2: =COUNT(Orders!$V$2:$V$501) -> 500
A3: Mean | B3: =AVERAGE(Orders!$V$2:$V$501) -> 25.11592
A4: Median | B4: =MEDIAN(Orders!$V$2:$V$501) -> 18.7335
A5: 95th percentile | B5: =PERCENTILE(Orders!$V$2:$V$501,0.95) -> 70.12805
A6: Minimum | B6: =MIN(Orders!$V$2:$V$501) -> 1.765
A7: Maximum | B7: =MAX(Orders!$V$2:$V$501) -> 101.875
A8: Standard deviation | B8: =STDEVP(Orders!$V$2:$V$501) -> 20.746261
A9: Mean – passed orders | B9: =AVERAGEIF(Orders!$Q$2:$Q$501,"pass",Orders!$V$2:$V$501) -> 24.237957
A10: Mean – warned orders | B10: =AVERAGEIF(Orders!$Q$2:$Q$501,"warn",Orders!$V$2:$V$501) -> 24.505667
A11: Mean – blocked orders | B11: =AVERAGEIF(Orders!$Q$2:$Q$501,"fail",Orders!$V$2:$V$501) -> 26.419745
A13: From (ms) | B13: To (ms) | C13: Orders
A14: 0 | B14: 5 | C14: =COUNTIFS(Orders!$V$2:$V$501,">="&A14,Orders!$V$2:$V$501,"<"&B14) -> 59
A15: 5 | B15: 10 | C15: =COUNTIFS(Orders!$V$2:$V$501,">="&A15,Orders!$V$2:$V$501,"<"&B15) -> 84
A16: 10 | B16: 15 | C16: =COUNTIFS(Orders!$V$2:$V$501,">="&A16,Orders!$V$2:$V$501,"<"&B16) -> 68
A17: 15 | B17: 20 | C17: =COUNTIFS(Orders!$V$2:$V$501,">="&A17,Orders!$V$2:$V$501,"<"&B17) -> 52
A18: 20 | B18: 25 | C18: =COUNTIFS(Orders!$V$2:$V$501,">="&A18,Orders!$V$2:$V$501,"<"&B18) -> 42
A19: 25 | B19: 30 | C19: =COUNTIFS(Orders!$V$2:$V$501,">="&A19,Orders!$V$2:$V$501,"<"&B19) -> 36
A20: 30 | B20: 35 | C20: =COUNTIFS(Orders!$V$2:$V$501,">="&A20,Orders!$V$2:$V$501,"<"&B20) -> 29
A21: 35 | B21: 40 | C21: =COUNTIFS(Orders!$V$2:$V$501,">="&A21,Orders!$V$2:$V$501,"<"&B21) -> 27
A22: 40 | B22: 45 | C22: =COUNTIFS(Orders!$V$2:$V$501,">="&A22,Orders!$V$2:$V$501,"<"&B22) -> 23
A23: 45 | B23: 50 | C23: =COUNTIFS(Orders!$V$2:$V$501,">="&A23,Orders!$V$2:$V$501,"<"&B23) -> 18
A24: 50 | B24: 55 | C24: =COUNTIFS(Orders!$V$2:$V$501,">="&A24,Orders!$V$2:$V$501,"<"&B24) -> 10
A25: 55 | B25: 60 | C25: =COUNTIFS(Orders!$V$2:$V$501,">="&A25,Orders!$V$2:$V$501,"<"&B25) -> 9
... A34: 100 | B34: 105 | C34: =COUNTIFS(Orders!$V$2:$V$501,">="&A34,Orders!$V$2:$V$501,"<"&B34) -> 2
A36: Measured inside the database (clock time around submit_order), Supabase Postgres 17, eu-west-1. Excludes network time to the browser.

Sheet Success criteria
A1: Objective | B1: Success criterion | C1: Measured result | D1: Status | E1: Evidence / note
A2: Build a digital order-processing system | B2: 500 successful simulated orders | C2: =COUNTA(Orders!$A$2:$A$501)&" orders processed" -> 500 orders processed | D2: Met | E2: Every order was saved, validated and routed by the live functions (Orders sheet).
A3: Validate orders automatically | B3: 90% validation accuracy | C3: =TEXT('Confusion matrix'!B8,"0.0%")&" on all orders; "&TEXT('Confusion matrix'!B20,"0.0%")&" on rule-covered errors" -> 83.4% on all orders; 92.0% on rule-covered errors | D3: Partly met | E3: Below 90% when realistic mistakes with no rule are included; above 90% on the error types the rules cover. 32 of 33 false alarms came from the unusual-quantity warning.
A4: Reduce manual data-entry errors | B4: 100% mandatory-field completion | C4: =TEXT(COUNTIFS(Orders!$S$2:$S$501,"pending_approval",Orders!$G$2:$G$501,"<>(none)")/COUNTIF(Orders!$S$2:$S$501,"pending_approval"),"0%")&" of orders reaching approval had every mandatory field" -> 100% of orders reaching approval had every mandatory field | D4: Met | E4: Orders missing a mandatory field cannot leave validation (blocked by the database).
A5: Reduce manual data-entry errors | B5: 60% reduction in manual errors | C5: Needs the manual baseline | D5: Pending | E5: ="Indicative only: the system flagged "&TEXT('Confusion matrix'!B10,"0.0%")&" of erroneous orders before approval. Record the baseline in the Manual baseline sheet to measure the real reduction." -> Indicative only: the system flagged 82.4% of erroneous orders before approval. Record the baseline in the Manual baseline sheet to measure the real reduction.
A6: Improve processing speed | B6: 30–50% faster processing | C6: =TEXT(Timing!B4,"0.0")&" ms median automatic validation per order" -> 18.7 ms median automatic validation per order | D6: Pending | E6: Automatic checking is near-instant, but the criterion compares end-to-end staff time; needs the manual baseline.

Sheet Manual baseline
A1: Manual-entry baseline – fill in the yellow cells (blue text). One row per sample order (about 30 recommended).
A2: Time a person re-keying each order from its original Excel/WhatsApp/e-mail message, count the errors they make, then do the same order in Verity.
A4: Sample # | B4: Source message | C4: Manual: time (seconds) | D4: Manual: errors made | E4: Verity: time (seconds) | F4: Verity: errors reaching approval | G4: Time saved
A5: 1 | B5: WhatsApp message | C5: 180 | D5: 1 | E5: 95 | F5: 0 | G5: =IF(OR(C5="",E5="",C5=0),"",1-E5/C5) -> 0.47222222
A6: 2 | G6: =IF(OR(C6="",E6="",C6=0),"",1-E6/C6)
A7: 3 | G7: =IF(OR(C7="",E7="",C7=0),"",1-E7/C7)
A8: 4 | G8: =IF(OR(C8="",E8="",C8=0),"",1-E8/C8)
A9: 5 | G9: =IF(OR(C9="",E9="",C9=0),"",1-E9/C9)
A10: 6 | G10: =IF(OR(C10="",E10="",C10=0),"",1-E10/C10)
A11: 7 | G11: =IF(OR(C11="",E11="",C11=0),"",1-E11/C11)
A12: 8 | G12: =IF(OR(C12="",E12="",C12=0),"",1-E12/C12)
A13: 9 | G13: =IF(OR(C13="",E13="",C13=0),"",1-E13/C13)
A14: 10 | G14: =IF(OR(C14="",E14="",C14=0),"",1-E14/C14)
A15: 11 | G15: =IF(OR(C15="",E15="",C15=0),"",1-E15/C15)
A16: 12 | G16: =IF(OR(C16="",E16="",C16=0),"",1-E16/C16)
A17: 13 | G17: =IF(OR(C17="",E17="",C17=0),"",1-E17/C17)
... A34: 30 | G34: =IF(OR(C34="",E34="",C34=0),"",1-E34/C34)
A36: Totals | C36: =SUM(C5:C34) -> 180 | D36: =SUM(D5:D34) -> 1 | E36: =SUM(E5:E34) -> 95 | F36: =SUM(F5:F34) -> 0
A38: Error reduction | C38: =IF(D36=0,"",1-F36/D36) -> 1 | D38: target: at least 60%
A39: Time saved | C39: =IF(C36=0,"",1-E36/C36) -> 0.47222222 | D39: target: 30–50%
A41: Row 5 is an example; overwrite or clear it. Yellow cells are inputs; column G and rows 36–39 calculate themselves.

Sheet R1 Orders
A1: Seq | B1: Order no. | C1: Simulated day | D1: Company | E1: Region | F1: Lines | G1: Units | H1: Items (SKU x qty @ unit price) | I1: Subtotal (₦) | J1: Delivery fee (₦) | K1: Tax (₦) | L1: Total (₦) | M1: Planted error | N1: Has rule | O1: Expected rule | P1: Outcome | Q1: Flagged | R1: Status after submit | S1: Rules triggered | T1: Messages shown | U1: Validation time (ms) | V1: Draft event at | W1: Submitted event at | X1: Last event at | Y1: Last status | Z1: Rule: mandatory | AA1: Rule: sku | AB1: Rule: quantity | AC1: Rule: stock | AD1: Rule: customer_status | AE1: Rule: pricing | AF1: Rule: delivery | AG1: Rule: duplicate | AH1: Rule: unusual_quantity | AI1: Delivery date given
A2: 1 | B2: ORD-3782 | C2: 1 | D2: Bodija Interiors | E2: (none) | F2: 1 | G2: 10 | H2: WIRE-25 x 10 @ 52,000 | I2: 520000 | J2: 0 | K2: 39000 | L2: 559000 | M2: Missing delivery address | N2: Yes | O2: mandatory | P2: fail | Q2: =IF(P2="pass","No","Yes") -> Yes | R2: validation_failed | S2: mandatory | T2: Choose a delivery address. | U2: 2.45 | V2: 2026-10-27T10:36:08.478438+00:00 | W2: 2026-10-27T10:36:08.480878+00:00 | X2: 2026-10-27T10:36:08.481309+00:00 | Y2: validation_failed | Z2: 1 | AA2: 0 | AB2: 0 | AC2: 0 | AD2: 0 | AE2: 0 | AF2: 0 | AG2: 0 | AH2: 0 | AI2: Yes
A3: 2 | B3: ORD-3783 | C3: 1 | D3: Gwarinpa Homes Ltd | E3: Abuja | F3: 1 | G3: 104 | H3: CEM-50 x 104 @ 9,500 | I3: 988000 | J3: 15000 | K3: 75225 | L3: 1078225 | M3: Missing delivery date | N3: Yes | O3: mandatory | P3: fail | Q3: =IF(P3="pass","No","Yes") -> Yes | R3: validation_failed | S3: mandatory, unusual_quantity | T3: Choose a delivery date. | Cement, 50 kg bag: 104 is far above this customer's usual 23. | U3: 5.675 | V3: 2026-10-27T10:36:08.4844+00:00 | W3: 2026-10-27T10:36:08.490012+00:00 | X3: 2026-10-27T10:36:08.490486+00:00 | Y3: validation_failed | Z3: 1 | AA3: 0 | AB3: 0 | AC3: 0 | AD3: 0 | AE3: 0 | AF3: 0 | AG3: 0 | AH3: 1 | AI3: No
A4: 3 | B4: ORD-3784 | C4: 1 | D4: Marina Point Facilities | E4: Lagos Island | F4: 4 | G4: 62 | H4: NAIL-3 x 1 @ 31,000; SAND-T x 1 @ 185,000; TIL-6060 x 48 @ 14,500; WIRE-25 x 12 @ 52,000 | I4: 1536000 | J4: 5000 | K4: 115575 | L4: 1656575 | M4: Discontinued product | N4: Yes | O4: sku | P4: fail | Q4: =IF(P4="pass","No","Yes") -> Yes | R4: validation_failed | S4: sku, stock | T4: SAND-T is no longer sold. Remove it. | Sharp sand, 20 tonne trip is out of stock. | U4: 2.85 | V4: 2026-10-27T10:36:08.492563+00:00 | W4: 2026-10-27T10:36:08.495723+00:00 | X4: 2026-10-27T10:36:08.496122+00:00 | Y4: validation_failed | Z4: 0 | AA4: 1 | AB4: 0 | AC4: 1 | AD4: 0 | AE4: 0 | AF4: 0 | AG4: 0 | AH4: 0 | AI4: Yes
A5: 4 | B5: ORD-3785 | C5: 1 | D5: Victoria Island Fit-Out Ltd | E5: Lagos Island | F5: 2 | G5: 13 | H5: WIRE-25 x 13 @ 52,000; PVC-4 x 2.5 (Quantity must be a whole number) | I5: 676000 | J5: 5000 | K5: 51075 | L5: 732075 | M5: Fractional quantity | N5: Yes | O5: quantity | P5: fail | Q5: =IF(P5="pass","No","Yes") -> Yes | R5: validation_failed | S5: quantity | T5: PVC-4 - Quantity must be a whole number | U5: 2.569 | V5: 2026-10-27T10:36:08.49845+00:00 | W5: 2026-10-27T10:36:08.50121+00:00 | X5: 2026-10-27T10:36:08.50162+00:00 | Y5: validation_failed | Z5: 0 | AA5: 0 | AB5: 1 | AC5: 0 | AD5: 0 | AE5: 0 | AF5: 0 | AG5: 0 | AH5: 0 | AI5: Yes
A6: 5 | B6: ORD-3786 | C6: 1 | D6: Bodija Interiors | E6: Ibadan | F6: 4 | G6: 648 | H6: NAIL-3 x 11 @ 31,000; ROD-12 x 586 @ 7,200; ROD-16 x 39 @ 11,800; WIRE-25 x 12 @ 52,000 | I6: 5644400 | J6: 9000 | K6: 424005 | L6: 6077405 | M6: Quantity above available stock | N6: Yes | O6: stock | P6: fail | Q6: =IF(P6="pass","No","Yes") -> Yes | R6: validation_failed | S6: stock, unusual_quantity | T6: Iron rod, 12 mm: not enough stock for this quantity. Reduce it. | Iron rod, 12 mm: 586 is far above this customer's usual 13. | U6: 6.146 | V6: 2026-10-27T10:36:08.503648+00:00 | W6: 2026-10-27T10:36:08.511376+00:00 | X6: 2026-10-27T10:36:08.511833+00:00 | Y6: validation_failed | Z6: 0 | AA6: 0 | AB6: 0 | AC6: 1 | AD6: 0 | AE6: 0 | AF6: 0 | AG6: 0 | AH6: 1 | AI6: Yes
A7: 6 | B7: ORD-3787 | C7: 1 | D7: Ajah Sunrise Housing Co-op | E7: Lekki-Ajah | F7: 4 | G7: 81 | H7: NAIL-3 x 9 @ 31,000; PNT-20C x 5 @ 38,000; ROD-16 x 67 @ 11,800; TIL-6060 x 2.5 (Quantity must be a whole number) | I7: 1259600 | J7: 6000 | K7: 94920 | L7: 1360520 | M7: Fractional quantity | N7: Yes | O7: quantity | P7: fail | Q7: =IF(P7="pass","No","Yes") -> Yes | R7: validation_failed | S7: quantity | T7: TIL-6060 - Quantity must be a whole number | U7: 2.585 | V7: 2026-10-27T10:36:08.513837+00:00 | W7: 2026-10-27T10:36:08.516723+00:00 | X7: 2026-10-27T10:36:08.517133+00:00 | Y7: validation_failed | Z7: 0 | AA7: 0 | AB7: 1 | AC7: 0 | AD7: 0 | AE7: 0 | AF7: 0 | AG7: 0 | AH7: 0 | AI7: Yes
A8: 7 | B8: ORD-3788 | C8: 1 | D8: Bodija Interiors | E8: Ibadan | F8: 1 | G8: 10 | H8: PNT-20C x 10 @ 38,000 | I8: 380000 | J8: 9000 | K8: 29175 | L8: 418175 | M8: Clean order (no error) | N8: No | P8: pass | Q8: =IF(P8="pass","No","Yes") -> No | R8: pending_approval | U8: 2.882 | V8: 2026-10-27T10:36:08.51894+00:00 | W8: 2026-10-27T10:36:08.521308+00:00 | X8: 2026-10-27T10:36:08.52173+00:00 | Y8: pending_approval | Z8: 0 | AA8: 0 | AB8: 0 | AC8: 0 | AD8: 0 | AE8: 0 | AF8: 0 | AG8: 0 | AH8: 0 | AI8: Yes
A9: 8 | B9: ORD-3789 | C9: 1 | D9: Marina Point Facilities | E9: Lagos Island | F9: 2 | G9: 57 | H9: PVC-2 x 2 @ 4,100; PVC-4 x 55 @ 8,600 | I9: 481200 | J9: 5000 | K9: 36465 | L9: 522665 | M9: Delivery date in the past | N9: Yes | O9: delivery | P9: fail | Q9: =IF(P9="pass","No","Yes") -> Yes | R9: validation_failed | S9: delivery | T9: The delivery date is in the past. | U9: 2.541 | V9: 2026-10-27T10:36:08.523454+00:00 | W9: 2026-10-27T10:36:08.526041+00:00 | X9: 2026-10-27T10:36:08.526487+00:00 | Y9: validation_failed | Z9: 0 | AA9: 0 | AB9: 0 | AC9: 0 | AD9: 0 | AE9: 0 | AF9: 1 | AG9: 0 | AH9: 0 | AI9: Yes
A10: 9 | B10: ORD-3790 | C10: 1 | D10: Ibadan Prime Homes Ltd | E10: Ibadan | F10: 3 | G10: 227 | H10: CEM-50 x 178 @ 9,500; PVC-2 x 2 @ 4,100; PVC-4 x 47 @ 8,600 | I10: 2103400 | J10: 9000 | K10: 158430 | L10: 2270830 | M10: Clean order (no error) | N10: No | P10: warn | Q10: =IF(P10="pass","No","Yes") -> Yes | R10: pending_approval | S10: unusual_quantity | T10: Cement, 50 kg bag: 178 is far above this customer's usual 23. | U10: 6.316 | V10: 2026-10-27T10:36:08.527486+00:00 | W10: 2026-10-27T10:36:08.533523+00:00 | X10: 2026-10-27T10:36:08.533951+00:00 | Y10: pending_approval | Z10: 0 | AA10: 0 | AB10: 0 | AC10: 0 | AD10: 0 | AE10: 0 | AF10: 0 | AG10: 0 | AH10: 1 | AI10: Yes
A11: 10 | B11: ORD-3791 | C11: 1 | D11: Zuma Rock Engineering | E11: Abuja | F11: 2 | G11: 8 | H11: NAIL-3 x 7 @ 31,000; PNT-20C x 1 @ 38,000 | I11: 255000 | J11: 15000 | K11: 20250 | L11: 290250 | M11: Clean order (no error) | N11: No | P11: pass | Q11: =IF(P11="pass","No","Yes") -> No | R11: pending_approval | U11: 3.322 | V11: 2026-10-27T10:36:08.535559+00:00 | W11: 2026-10-27T10:36:08.53968+00:00 | X11: 2026-10-27T10:36:08.540085+00:00 | Y11: pending_approval | Z11: 0 | AA11: 0 | AB11: 0 | AC11: 0 | AD11: 0 | AE11: 0 | AF11: 0 | AG11: 0 | AH11: 0 | AI11: Yes
A12: 11 | B12: ORD-3792 | C12: 1 | D12: Ajah Sunrise Housing Co-op | E12: Lekki-Ajah | F12: 3 | G12: 253 | H12: CEM-50 x 190 @ 9,500; PNT-20W x 29 @ 38,000; PVC-4 x 34 @ 8,600 | I12: 3199400 | J12: 6000 | K12: 240405 | L12: 3445805 | M12: Plausible quantity typing slip | N12: No | P12: warn | Q12: =IF(P12="pass","No","Yes") -> Yes | R12: pending_approval | S12: unusual_quantity | T12: Cement, 50 kg bag: 190 is far above this customer's usual 23. | U12: 6.706 | V12: 2026-10-27T10:36:08.541948+00:00 | W12: 2026-10-27T10:36:08.548443+00:00 | X12: 2026-10-27T10:36:08.548891+00:00 | Y12: pending_approval | Z12: 0 | AA12: 0 | AB12: 0 | AC12: 0 | AD12: 0 | AE12: 0 | AF12: 0 | AG12: 0 | AH12: 1 | AI12: Yes
A13: 12 | B13: ORD-3793 | C13: 1 | D13: Lekki Coastal Developers | E13: Lekki-Ajah | F13: 3 | G13: 1126 | H13: ROD-16 x 73 @ 11,800; ROOF-AL x 1043 @ 12,500; TIL-6060 x 10 @ 14,500 | I13: 14043900 | J13: 6000 | K13: 1053742.5 | L13: 15103642 | M13: Quantity above maximum | N13: Yes | O13: quantity | P13: fail | Q13: =IF(P13="pass","No","Yes") -> Yes | R13: validation_failed | S13: quantity, stock | T13: Aluminium roofing sheet, 0.55 mm: quantity must be between 10 and 1000. | Aluminium roofing sheet, 0.55 mm: not enough stock for this quantity. Reduce it. | U13: 3.082 | V13: 2026-10-27T10:36:08.550631+00:00 | W13: 2026-10-27T10:36:08.553931+00:00 | X13: 2026-10-27T10:36:08.554356+00:00 | Y13: validation_failed | Z13: 0 | AA13: 0 | AB13: 1 | AC13: 1 | AD13: 0 | AE13: 0 | AF13: 0 | AG13: 0 | AH13: 0 | AI13: Yes
A14: 13 | B14: ORD-3794 | C14: 1 | D14: Bodija Interiors | E14: Ibadan | F14: 2 | G14: 31 | H14: ROD-12 x 12 @ 7,200; ROD-16 x 19 @ 11,800 | I14: 310600 | J14: 9000 | K14: 23970 | L14: 343570 | M14: Clean order (no error) | N14: No | P14: pass | Q14: =IF(P14="pass","No","Yes") -> No | R14: pending_approval | U14: 6.755 | V14: 2026-10-27T10:36:08.560981+00:00 | W14: 2026-10-27T10:36:08.568594+00:00 | X14: 2026-10-27T10:36:08.56906+00:00 | Y14: pending_approval | Z14: 0 | AA14: 0 | AB14: 0 | AC14: 0 | AD14: 0 | AE14: 0 | AF14: 0 | AG14: 0 | AH14: 0 | AI14: Yes
A15: 14 | B15: ORD-3795 | C15: 1 | D15: Ajah Sunrise Housing Co-op | E15: Lekki-Ajah | F15: 3 | G15: 70 | H15: PNT-20C x 7 @ 38,000; PVC-2 x 2 @ 4,100; PVC-4 x 61 @ 8,600 | I15: 798800 | J15: 6000 | K15: 60360 | L15: 865160 | M15: Clean order (no error) | N15: No | P15: pass | Q15: =IF(P15="pass","No","Yes") -> No | R15: pending_approval | U15: 3.666 | V15: 2026-10-27T10:36:08.570777+00:00 | W15: 2026-10-27T10:36:08.573972+00:00 | X15: 2026-10-27T10:36:08.574559+00:00 | Y15: pending_approval | Z15: 0 | AA15: 0 | AB15: 0 | AC15: 0 | AD15: 0 | AE15: 0 | AF15: 0 | AG15: 0 | AH15: 0 | AI15: Yes
A16: 15 | B16: ORD-3796 | C16: 1 | D16: Kanu Brothers Building Supplies | E16: Lagos Mainland | F16: 3 | G16: 18 | H16: NAIL-3 x 1 @ 31,000; PNT-20C x 8 @ 38,000; PVC-4 x 9 @ 8,600 | I16: 412400 | J16: 4000 | K16: 31230 | L16: 447630 | M16: Clean order (no error) | N16: No | P16: pass | Q16: =IF(P16="pass","No","Yes") -> No | R16: pending_approval | U16: 4.972 | V16: 2026-10-27T10:36:08.576275+00:00 | W16: 2026-10-27T10:36:08.580984+00:00 | X16: 2026-10-27T10:36:08.581428+00:00 | Y16: pending_approval | Z16: 0 | AA16: 0 | AB16: 0 | AC16: 0 | AD16: 0 | AE16: 0 | AF16: 0 | AG16: 0 | AH16: 0 | AI16: Yes
A17: 16 | B17: ORD-3797 | C17: 1 | D17: Adeyemi & Sons Construction Ltd | E17: Ikeja | F17: 1 | G17: 25 | H17: ROD-16 x 25 @ 11,800 | I17: 295000 | J17: 4500 | K17: 22462.5 | L17: 321962.5 | M17: Clean order (no error) | N17: No | P17: pass | Q17: =IF(P17="pass","No","Yes") -> No | R17: pending_approval | U17: 3.037 | V17: 2026-10-27T10:36:08.583089+00:00 | W17: 2026-10-27T10:36:08.585657+00:00 | X17: 2026-10-27T10:36:08.58609+00:00 | Y17: pending_approval | Z17: 0 | AA17: 0 | AB17: 0 | AC17: 0 | AD17: 0 | AE17: 0 | AF17: 0 | AG17: 0 | AH17: 0 | AI17: Yes
A18: 17 | B18: ORD-3798 | C18: 1 | D18: Gwarinpa Homes Ltd | E18: Abuja | F18: 1 | G18: 2 | H18: PVC-2 x 2 @ 4,100 | I18: 8200 | J18: 15000 | K18: 1740 | L18: 24940 | M18: Customer account not active | N18: Yes | O18: customer_status | P18: fail | Q18: =IF(P18="pass","No","Yes") -> Yes | R18: validation_failed | S18: customer_status | T18: The customer account is not active. | U18: 3.207 | V18: 2026-10-27T10:36:08.58771+00:00 | W18: 2026-10-27T10:36:08.590485+00:00 | X18: 2026-10-27T10:36:08.591564+00:00 | Y18: validation_failed | Z18: 0 | AA18: 0 | AB18: 0 | AC18: 0 | AD18: 1 | AE18: 0 | AF18: 0 | AG18: 0 | AH18: 0 | AI18: Yes
A19: 18 | B19: ORD-3799 | C19: 1 | D19: Zuma Rock Engineering | E19: Abuja | F19: 2 | G19: 43 | H19: CEM-50 x 22 @ 9,500; ROOF-AL x 21 @ 12,500 | I19: 471500 | J19: 15000 | K19: 36487.5 | L19: 522987.5 | M19: Customer account not active | N19: Yes | O19: customer_status | P19: fail | Q19: =IF(P19="pass","No","Yes") -> Yes | R19: validation_failed | S19: customer_status | T19: The customer account is not active. | U19: 6.128 | V19: 2026-10-27T10:36:08.592892+00:00 | W19: 2026-10-27T10:36:08.599224+00:00 | X19: 2026-10-27T10:36:08.599662+00:00 | Y19: validation_failed | Z19: 0 | AA19: 0 | AB19: 0 | AC19: 0 | AD19: 1 | AE19: 0 | AF19: 0 | AG19: 0 | AH19: 0 | AI19: Yes
A20: 19 | B20: ORD-3800 | C20: 1 | D20: Marina Point Facilities | E20: Lagos Island | F20: 3 | G20: 37 | H20: PNT-20W x 14 @ 38,000; ROD-16 x 23 @ 11,800; XX-680 x None (not in the catalogue) | I20: 803400 | J20: 5000 | K20: 60630 | L20: 869030 | M20: SKU not in catalogue | N20: Yes | O20: sku | P20: fail | Q20: =IF(P20="pass","No","Yes") -> Yes | R20: validation_failed | S20: sku | T20: Row 4: XX-680 - not in the catalogue | U20: 2.854 | V20: 2026-10-27T10:36:08.601213+00:00 | W20: 2026-10-27T10:36:08.604148+00:00 | X20: 2026-10-27T10:36:08.604599+00:00 | Y20: validation_failed | Z20: 0 | AA20: 1 | AB20: 0 | AC20: 0 | AD20: 0 | AE20: 0 | AF20: 0 | AG20: 0 | AH20: 0 | AI20: Yes
A21: 20 | B21: ORD-3801 | C21: 1 | D21: Greenfield Estates Nigeria | E21: Lekki-Ajah | F21: 2 | G21: 18 | H21: PNT-20C x 1 @ 38,000; ROOF-AL x 17 @ 12,500 | I21: 250500 | J21: 6000 | K21: 19237.5 | L21: 275737.5 | M21: Clean order (no error) | N21: No | P21: pass | Q21: =IF(P21="pass","No","Yes") -> No | R21: pending_approval | U21: 3.353 | V21: 2026-10-27T10:36:08.605834+00:00 | W21: 2026-10-27T10:36:08.610085+00:00 | X21: 2026-10-27T10:36:08.610526+00:00 | Y21: pending_approval | Z21: 0 | AA21: 0 | AB21: 0 | AC21: 0 | AD21: 0 | AE21: 0 | AF21: 0 | AG21: 0 | AH21: 0 | AI21: Yes
A22: 21 | B22: ORD-3802 | C22: 1 | D22: Oyo Central Builders | E22: Ibadan | F22: 1 | G22: 22 | H22: CEM-50 x 22 @ 9,500 | I22: 209000 | J22: 9000 | K22: 16350 | L22: 234350 | M22: Price changed after the order was saved | N22: Yes | O22: pricing | P22: fail | Q22: =IF(P22="pass","No","Yes") -> Yes | R22: validation_failed | S22: pricing | T22: Cement, 50 kg bag: price changed from 9500.00 to 10000.00. Save the order again to update it. | U22: 6.2 | V22: 2026-10-27T10:36:08.612522+00:00 | W22: 2026-10-27T10:36:08.619036+00:00 | X22: 2026-10-27T10:36:08.619481+00:00 | Y22: validation_failed | Z22: 0 | AA22: 0 | AB22: 0 | AC22: 0 | AD22: 0 | AE22: 1 | AF22: 0 | AG22: 0 | AH22: 0 | AI22: Yes
A23: 22 | B23: ORD-3803 | C23: 1 | D23: Apapa Port Works Supplies | E23: Lagos Mainland | F23: 2 | G23: 1559 | H23: PNT-20W x 21 @ 38,000; ROD-12 x 1538 @ 7,200 | I23: 11871600 | J23: 4000 | K23: 890670 | L23: 12766270 | M23: Quantity above maximum | N23: Yes | O23: quantity | P23: fail | Q23: =IF(P23="pass","No","Yes") -> Yes | R23: validation_failed | S23: quantity, stock, unusual_quantity | T23: Iron rod, 12 mm: quantity must be between 5 and 1500. | Iron rod, 12 mm: not enough stock for this quantity. Reduce it. | Iron rod, 12 mm: 1538 is far above this customer's usual 13. | U23: 6.829 | V23: 2026-10-27T10:36:08.621248+00:00 | W23: 2026-10-27T10:36:08.628177+00:00 | X23: 2026-10-27T10:36:08.62862+00:00 | Y23: validation_failed | Z23: 0 | AA23: 0 | AB23: 1 | AC23: 1 | AD23: 0 | AE23: 0 | AF23: 0 | AG23: 0 | AH23: 1 | AI23: Yes
A24: 23 | B24: ORD-3804 | C24: 1 | D24: Oyo Central Builders | E24: Ibadan | F24: 2 | G24: 74 | H24: PNT-20W x 18 @ 38,000; TIL-6060 x 56 @ 14,500 | I24: 1496000 | J24: 9000 | K24: 112875 | L24: 1617875 | M24: Clean order (no error) | N24: No | P24: pass | Q24: =IF(P24="pass","No","Yes") -> No | R24: pending_approval | U24: 5.953 | V24: 2026-10-27T10:36:08.629974+00:00 | W24: 2026-10-27T10:36:08.632975+00:00 | X24: 2026-10-27T10:36:08.633437+00:00 | Y24: pending_approval | Z24: 0 | AA24: 0 | AB24: 0 | AC24: 0 | AD24: 0 | AE24: 0 | AF24: 0 | AG24: 0 | AH24: 0 | AI24: Yes
A25: 24 | B25: ORD-3805 | C25: 1 | D25: Magodo Residential Ltd | E25: Ikeja | F25: 2 | G25: 16 | H25: PNT-20W x 15 @ 38,000; PVC-2 x 1 @ 4,100 | I25: 574100 | J25: 4500 | K25: 43395 | L25: 621995 | M25: Quantity below minimum | N25: Yes | O25: quantity | P25: fail | Q25: =IF(P25="pass","No","Yes") -> Yes | R25: validation_failed | S25: quantity | T25: PVC pipe, 2 inch, 6 m: quantity must be between 2 and 500. | U25: 2.894 | V25: 2026-10-27T10:36:08.638047+00:00 | W25: 2026-10-27T10:36:08.641074+00:00 | X25: 2026-10-27T10:36:08.641507+00:00 | Y25: validation_failed | Z25: 0 | AA25: 0 | AB25: 1 | AC25: 0 | AD25: 0 | AE25: 0 | AF25: 0 | AG25: 0 | AH25: 0 | AI25: Yes
A26: 25 | B26: ORD-3806 | C26: 1 | D26: Gwarinpa Homes Ltd | E26: Abuja | F26: 3 | G26: 39 | H26: NAIL-3 x 3 @ 31,000; PNT-20W x 14 @ 38,000; TIL-6060 x 22 @ 14,500 | I26: 944000 | J26: 15000 | K26: 71925 | L26: 1030925 | M26: Wrong but valid product | N26: No | P26: pass | Q26: =IF(P26="pass","No","Yes") -> No | R26: pending_approval | U26: 5.086 | V26: 2026-10-27T10:36:08.64332+00:00 | W26: 2026-10-27T10:36:08.64799+00:00 | X26: 2026-10-27T10:36:08.648492+00:00 | Y26: pending_approval | Z26: 0 | AA26: 0 | AB26: 0 | AC26: 0 | AD26: 0 | AE26: 0 | AF26: 0 | AG26: 0 | AH26: 0 | AI26: Yes
A27: 26 | B27: ORD-3807 | C27: 1 | D27: Adeyemi & Sons Construction Ltd | E27: Ikeja | F27: 4 | G27: 170 | H27: PNT-20W x 26 @ 38,000; PVC-2 x 6 @ 4,100; ROD-12 x 117 @ 7,200; TIL-6060 x 21 @ 14,500 | I27: 2159500 | J27: 4500 | K27: 162300 | L27: 2326300 | M27: Wrong but valid product | N27: No | P27: warn | Q27: =IF(P27="pass","No","Yes") -> Yes | R27: pending_approval | S27: unusual_quantity | T27: Iron rod, 12 mm: 117 is far above this customer's usual 13. | U27: 12.497 | V27: 2026-10-27T10:36:08.650577+00:00 | W27: 2026-10-27T10:36:08.658325+00:00 | X27: 2026-10-27T10:36:08.663334+00:00 | Y27: pending_approval | Z27: 0 | AA27: 0 | AB27: 0 | AC27: 0 | AD27: 0 | AE27: 0 | AF27: 0 | AG27: 0 | AH27: 1 | AI27: Yes
A28: 27 | B28: ORD-3808 | C28: 1 | D28: Lekki Coastal Developers | E28: (none) | F28: 2 | G28: 27 | H28: PVC-4 x 17 @ 8,600; WIRE-25 x 10 @ 52,000 | I28: 666200 | J28: 0 | K28: 49965 | L28: 716165 | M28: Missing delivery address | N28: Yes | O28: mandatory | P28: fail | Q28: =IF(P28="pass","No","Yes") -> Yes | R28: validation_failed | S28: mandatory | T28: Choose a delivery address. | U28: 2.908 | V28: 2026-10-27T10:36:08.665525+00:00 | W28: 2026-10-27T10:36:08.668539+00:00 | X28: 2026-10-27T10:36:08.668976+00:00 | Y28: validation_failed | Z28: 1 | AA28: 0 | AB28: 0 | AC28: 0 | AD28: 0 | AE28: 0 | AF28: 0 | AG28: 0 | AH28: 0 | AI28: Yes
A29: 28 | B29: ORD-3809 | C29: 1 | D29: Greenfield Estates Nigeria | E29: Lekki-Ajah | F29: 3 | G29: 157 | H29: PNT-20W x 3 @ 38,000; ROD-12 x 90 @ 7,200; ROOF-AL x 64 @ 12,500 | I29: 1562000 | J29: 6000 | K29: 117600 | L29: 1685600 | M29: Plausible quantity typing slip | N29: No | P29: warn | Q29: =IF(P29="pass","No","Yes") -> Yes | R29: pending_approval | S29: unusual_quantity | T29: Iron rod, 12 mm: 90 is far above this customer's usual 13. | U29: 7.869 | V29: 2026-10-27T10:36:08.670462+00:00 | W29: 2026-10-27T10:36:08.678025+00:00 | X29: 2026-10-27T10:36:08.678491+00:00 | Y29: pending_approval | Z29: 0 | AA29: 0 | AB29: 0 | AC29: 0 | AD29: 0 | AE29: 0 | AF29: 0 | AG29: 0 | AH29: 1 | AI29: Yes
